<?xml version="1.0" encoding="utf-8"?>
<!-- This URDF was automatically created by SolidWorks to URDF Exporter! Originally created by Stephen Brawner (brawner@gmail.com) 
     Commit Version: 1.6.0-4-g7f85cfe  Build Version: 1.6.7995.38578
     For more information, please see http://wiki.ros.org/sw_urdf_exporter -->
<robot
  name="diff_drive_bot_with_lidar">
  <link
    name="base_link">
    <inertial>
      <origin
        xyz="-0.0053991 -0.0020273 0.00085493"
        rpy="0 0 0" />
      <mass
        value="2.7764" />
      <inertia
        ixx="0.0094878"
        ixy="6.6341E-06"
        ixz="-0.00024936"
        iyy="0.018479"
        iyz="7.2428E-05"
        izz="0.024302" />
    </inertial>
    <visual>
      <origin
        xyz="0 0 0"
        rpy="0 0 0" />
      <geometry>
        <mesh
          filename="package://diff_drive_bot_with_lidar/meshes/base_link.STL" />
      </geometry>
      <material
        name="">
        <color
          rgba="0.79216 0.81961 0.93333 1" />
      </material>
    </visual>
    <collision>
      <origin
        xyz="0 0 0"
        rpy="0 0 0" />
      <geometry>
        <mesh
          filename="package://diff_drive_bot_with_lidar/meshes/base_link.STL" />
      </geometry>
    </collision>
  </link>
  <link
    name="left_link">
    <inertial>
      <origin
        xyz="0 -0.019022 0"
        rpy="0 0 0" />
      <mass
        value="0.21583" />
      <inertia
        ixx="0.00012343"
        ixy="7.8345E-22"
        ixz="2.7387E-21"
        iyy="0.00019474"
        iyz="-2.2027E-21"
        izz="0.00012343" />
    </inertial>
    <visual>
      <origin
        xyz="0 0 0"
        rpy="0 0 0" />
      <geometry>
        <mesh
          filename="package://diff_drive_bot_with_lidar/meshes/left_link.STL" />
      </geometry>
      <material
        name="">
        <color
          rgba="0.79216 0.81961 0.93333 1" />
      </material>
    </visual>
    <collision>
      <origin
        xyz="0 0 0"
        rpy="0 0 0" />
      <geometry>
        <mesh
          filename="package://diff_drive_bot_with_lidar/meshes/left_link.STL" />
      </geometry>
    </collision>
  </link>
  <joint
    name="left_wheel"
    type="continuous">
    <origin
      xyz="-0.13867 0.13992 -0.042"
      rpy="0 0 0" />
    <parent
      link="base_link" />
    <child
      link="left_link" />
    <axis
      xyz="0 1 0" />
    <limit
      effort="1"
      velocity="10" />
  </joint>
  <link
    name="right_link">
    <inertial>
      <origin
        xyz="-2.7756E-17 0.019022 6.245E-17"
        rpy="0 0 0" />
      <mass
        value="0.21583" />
      <inertia
        ixx="0.00012343"
        ixy="1.0379E-19"
        ixz="6.8567E-21"
        iyy="0.00019474"
        iyz="2.451E-21"
        izz="0.00012343" />
    </inertial>
    <visual>
      <origin
        xyz="0 0 0"
        rpy="0 0 0" />
      <geometry>
        <mesh
          filename="package://diff_drive_bot_with_lidar/meshes/right_link.STL" />
      </geometry>
      <material
        name="">
        <color
          rgba="0.79216 0.81961 0.93333 1" />
      </material>
    </visual>
    <collision>
      <origin
        xyz="0 0 0"
        rpy="0 0 0" />
      <geometry>
        <mesh
          filename="package://diff_drive_bot_with_lidar/meshes/right_link.STL" />
      </geometry>
    </collision>
  </link>
  <joint
    name="right_wheel"
    type="continuous">
    <origin
      xyz="-0.13867 -0.14208 -0.042"
      rpy="0 0 0" />
    <parent
      link="base_link" />
    <child
      link="right_link" />
    <axis
      xyz="0 1 0" />
    <limit
      effort="1"
      velocity="10" />
  </joint>
  <gazebo>
      <plugin name="differential_drive_controller" filename="libgazebo_ros_diff_drive.so">
          <rosDebugLevel>Debug</rosDebugLevel>
          <publishWheelTF>false</publishWheelTF>
          <robotNamespace>/</robotNamespace>
          <publishTf>1</publishTf>
          <publishWheelJointState>false</publishWheelJointState>
          <alwaysOn>true</alwaysOn>
          <updateRate>100.0</updateRate>
          <leftJoint>left_wheel</leftJoint>
          <rightJoint>right_wheel</rightJoint>
          <wheelSeparation>0.341</wheelSeparation>
          <wheelDiameter>.17</wheelDiameter>
          <broadcastTF>1</broadcastTF>
          <wheelTorque>200</wheelTorque>
          <wheelAcceleration>10</wheelAcceleration>
          <commandTopic>cmd_vel</commandTopic>
          <odometryFrame>odom</odometryFrame>
          <odometryTopic>odom</odometryTopic>
          <pose_covariance_diagonal>[1.0, 1.0, 0.0, 0.0, 0.0, 1.0]</pose_covariance_diagonal>
          <twist_covariance_diagonal>[0.01, 0.0, 0.0, 0.0, 0.0, 0.1]</twist_covariance_diagonal>
          <gaussianNoise>0.05</gaussianNoise>
          <robotBaseFrame>base_link</robotBaseFrame>
          <legacyMode>false</legacyMode>
          <publishOdomTF>true</publishOdomTF>
          <odometrySource>world</odometrySource>
      </plugin>
    </gazebo>


</robot>