<?xml version="1.0" encoding="utf-8"?>
<!-- This URDF was automatically created by SolidWorks to URDF Exporter! Originally created by Stephen Brawner (brawner@gmail.com) 
     Commit Version: 1.6.0-4-g7f85cfe  Build Version: 1.6.7995.38578
     For more information, please see http://wiki.ros.org/sw_urdf_exporter -->
<robot
  name="diff_drive_bot_with_lidar">
  <!-- Base Link -->
  <link
    name="base_link">
    <inertial>
      <origin
        xyz="-0.0053990623924606 -0.00202726410040596 0.000854930489926943"
        rpy="0 0 0" />
      <mass
        value="2.77638109182328" />
      <inertia
        ixx="0.00948784051144306"
        ixy="6.63406828267113E-06"
        ixz="-0.000249360576627683"
        iyy="0.0184790006981357"
        iyz="7.24277999880761E-05"
        izz="0.0243022838556667" />
    </inertial>
    <visual>
      <origin
        xyz="0 0 0"
        rpy="0 0 0" />
      <geometry>
        <mesh
          filename="package://diff_drive_bot_with_lidar/meshes/base_link.STL" />
      </geometry>
      <material
        name="">
        <color
          rgba="0.792156862745098 0.819607843137255 0.933333333333333 1" />
      </material>
    </visual>
    <collision>
      <origin
        xyz="0 0 0"
        rpy="0 0 0" />
      <geometry>
        <mesh
          filename="package://diff_drive_bot_with_lidar/meshes/base_link.STL" />
      </geometry>
    </collision>
  </link>
  <!-- Left Wheel Link -->
  <link
    name="left_link">
    <inertial>
      <origin
        xyz="0 -0.0190218340611354 0"
        rpy="0 0 0" />
      <mass
        value="0.215827415301619" />
      <inertia
        ixx="0.000123433445533082"
        ixy="7.83452221612012E-22"
        ixz="2.73872631878343E-21"
        iyy="0.00019474241985751"
        iyz="-2.20269327702413E-21"
        izz="0.000123433445533082" />
    </inertial>
    <visual>
      <origin
        xyz="0 0 0"
        rpy="0 0 0" />
      <geometry>
        <mesh
          filename="package://diff_drive_bot_with_lidar/meshes/left_link.STL" />
      </geometry>
      <material
        name="">
        <color
          rgba="0.792156862745098 0.819607843137255 0.933333333333333 1" />
      </material>
    </visual>
    <collision>
      <origin
        xyz="0 0 0"
        rpy="0 0 0" />
      <geometry>
        <mesh
          filename="package://diff_drive_bot_with_lidar/meshes/left_link.STL" />
      </geometry>
    </collision>
  </link>
  <!-- left Wheel Joint -->
  <joint
    name="left_wheel"
    type="continuous">
    <origin
      xyz="-0.138666895478107 0.139916380652366 -0.042"
      rpy="0 0 0" />
    <parent
      link="base_link" />
    <child
      link="left_link" />
    <axis
      xyz="0 1 0" />
    <limit
      effort="1"
      velocity="10" />
  </joint>
  <!-- Right Wheel Link -->
  <link
    name="right_link">
    <inertial>
      <origin
        xyz="-2.77555756156289E-17 0.0190218340611352 6.24500451351651E-17"
        rpy="0 0 0" />
      <mass
        value="0.215827415301619" />
      <inertia
        ixx="0.000123433445533082"
        ixy="1.037934886211E-19"
        ixz="6.85672450250494E-21"
        iyy="0.00019474241985751"
        iyz="2.45101844653965E-21"
        izz="0.000123433445533082" />
    </inertial>
    <visual>
      <origin
        xyz="0 0 0"
        rpy="0 0 0" />
      <geometry>
        <mesh
          filename="package://diff_drive_bot_with_lidar/meshes/right_link.STL" />
      </geometry>
      <material
        name="">
        <color
          rgba="0.792156862745098 0.819607843137255 0.933333333333333 1" />
      </material>
    </visual>
    <collision>
      <origin
        xyz="0 0 0"
        rpy="0 0 0" />
      <geometry>
        <mesh
          filename="package://diff_drive_bot_with_lidar/meshes/right_link.STL" />
      </geometry>
    </collision>
  </link>
  <!-- Right Wheel Joint -->
  <joint
    name="right_wheel"
    type="continuous">
    <origin
      xyz="-0.138666895478107 -0.142083619347635 -0.042"
      rpy="0 0 0" />
    <parent
      link="base_link" />
    <child
      link="right_link" />
    <axis
      xyz="0 1 0" />
    <limit
      effort="1"
      velocity="10" />
  </joint>
  <!-- Lidar Base Link -->
  <link
    name="lidar_base_link">
    <inertial>
      <origin
        xyz="0.000770143208244409 9.13050673398592E-05 0.00538459519764828"
        rpy="0 0 0" />
      <mass
        value="1.33982083389145" />
      <inertia
        ixx="0.0006362630403681"
        ixy="-8.02177273880031E-07"
        ixz="-0.000158331117915163"
        iyy="0.000987772574098984"
        iyz="3.05694464144642E-06"
        izz="0.0011146309302405" />
    </inertial>
    <visual>
      <origin
        xyz="0 0 0"
        rpy="0 0 0" />
      <geometry>
        <mesh
          filename="package://diff_drive_bot_with_lidar/meshes/lidar_base_link.STL" />
      </geometry>
      <material
        name="">
        <color
          rgba="0.792156862745098 0.819607843137255 0.933333333333333 1" />
      </material>
    </visual>
    <collision>
      <origin
        xyz="0 0 0"
        rpy="0 0 0" />
      <geometry>
        <mesh
          filename="package://diff_drive_bot_with_lidar/meshes/lidar_base_link.STL" />
      </geometry>
    </collision>
  </link>
  <!-- Lidar Base Joint -->
  <joint
    name="lidar_base_joint"
    type="fixed">
    <origin
      xyz="-0.0103343023948472 -0.00359165195948655 0.1"
      rpy="0 0 -0.0530343084887313" />
    <parent
      link="base_link" />
    <child
      link="lidar_base_link" />
    <axis
      xyz="0 0 0" />
  </joint>

  <!-- Lidar Rotor Link -->
  <link
    name="lidar_rot_link">
    <inertial>
      <origin
        xyz="-5.16946132002646E-05 9.61182608804597E-05 -0.0141231381853937"
        rpy="0 0 0" />
      <mass
        value="0.838797463919277" />
      <inertia
        ixx="0.000311324977727034"
        ixy="-1.70261713337164E-07"
        ixz="-3.08153674158863E-08"
        iyy="0.000311549492076468"
        iyz="5.84073905617686E-08"
        izz="0.000513492578102435" />
    </inertial>
    <visual>
      <origin
        xyz="0 0 0"
        rpy="0 0 0" />
      <geometry>
        <mesh
          filename="package://diff_drive_bot_with_lidar/meshes/lidar_rot_link.STL" />
      </geometry>
      <material
        name="">
        <color
          rgba="0.792156862745098 0.819607843137255 0.933333333333333 1" />
      </material>
    </visual>
    <collision>
      <origin
        xyz="0 0 0"
        rpy="0 0 0" />
      <geometry>
        <mesh
          filename="package://diff_drive_bot_with_lidar/meshes/lidar_rot_link.STL" />
      </geometry>
    </collision>
  </link>
  <!-- Lidar Rotor Joint -->
  <joint
    name="lidar_rot_joint"
    type="continuous">
    <origin
      xyz="-0.00275728157019983 -0.00409611162826763 0.1281"
      rpy="0 0 -0.0530343084887313" />
    <parent
      link="base_link" />
    <child
      link="lidar_rot_link" />
    <axis
      xyz="0 0 1" />
    <limit
      effort="1"
      velocity="1" />
  </joint>
  <!-- Lidar Rotor Reference -->
  <gazebo reference="lidar_rot_link">
    <material>Gazebo/RedGlow</material>
    <mu1>0</mu1>
    <mu2>0</mu2>
    <sensor type="ray" name="lidar">
      <always_on>true</always_on>
      <pose>0.035 0 -0.0125 0 0 0</pose>
      <visualize>false</visualize>
      <update_rate>10</update_rate>
      <ray>
        <scan>
          <horizontal>
            <samples>400</samples>
            <resolution>1</resolution>
            <min_angle>-3.14159</min_angle>
            <max_angle>3.14159</max_angle>
          </horizontal>
        </scan>  
        <range>
          <min>0.15</min>
          <max>6.0</max>
          <resolution>0.01</resolution>
        </range>
        <noise>
          <type>gaussian</type>
          <mean>0.0</mean>
          <stddev>0.01</stddev>
        </noise>
      </ray>

      <plugin name="gazebo_ros_head_rplidar_controller" filename="libgazebo_ros_gpu_laser.so">
        <topicName>/scan</topicName>
        <frameName>lidar_rot_link</frameName>

      </plugin>
    </sensor>
  </gazebo>

  <gazebo>
    <plugin name="differential_drive_controller" filename="libgazebo_ros_diff_drive.so">
      <rosDebugLevel>Debug</rosDebugLevel>
      <publishWheelTF>false</publishWheelTF>
      <robotNamespace>/</robotNamespace>
      <publishTf>1</publishTf>
      <publishWheelJointState>false</publishWheelJointState>
      <alwaysOn>true</alwaysOn>
      <updateRate>100.0</updateRate>
      <leftJoint>left_wheel</leftJoint>
      <rightJoint>right_wheel</rightJoint>
      <wheelSeparation>0.341</wheelSeparation>
      <wheelDiameter>.17</wheelDiameter>
      <broadcastTF>1</broadcastTF>
      <wheelTorque>200</wheelTorque>
      <wheelAcceleration>10</wheelAcceleration>
      <commandTopic>cmd_vel</commandTopic>
      <odometryFrame>odom</odometryFrame>
      <odometryTopic>odom</odometryTopic>
      <pose_covariance_diagonal>[1.0, 1.0, 0.0, 0.0, 0.0, 1.0]</pose_covariance_diagonal>
      <twist_covariance_diagonal>[0.01, 0.0, 0.0, 0.0, 0.0, 0.1]</twist_covariance_diagonal>
      <gaussianNoise>0.05</gaussianNoise>
      <robotBaseFrame>base_link</robotBaseFrame>
      <legacyMode>false</legacyMode>
      <publishOdomTF>true</publishOdomTF>
      <odometrySource>world</odometrySource>
    </plugin>
  </gazebo>


</robot>