<?xml version="1.0" encoding="utf-8"?>
<!-- This URDF was automatically created by SolidWorks to URDF Exporter! Originally created by Stephen Brawner (brawner@gmail.com) 
     Commit Version: 1.6.0-4-g7f85cfe  Build Version: 1.6.7995.38578
     For more information, please see http://wiki.ros.org/sw_urdf_exporter -->
<robot
  name="diffdrivebot">
  <link
    name="base_link">
    <inertial>
      <origin
        xyz="-0.00606746293762698 -1.17092309653188E-17 -0.0159067470445845"
        rpy="0 0 0" />
      <mass
        value="1.72841411222593" />
      <inertia
        ixx="0.00638027154313441"
        ixy="-8.64628670096283E-18"
        ixz="-0.000131521619785547"
        iyy="0.0153647157213499"
        iyz="-8.34109134255007E-19"
        izz="0.0212209304244771" />
    </inertial>
    <visual>
      <origin
        xyz="0 0 0"
        rpy="0 0 0" />
      <geometry>
        <mesh
          filename="package://diffdrivebot/meshes/base_link.STL" />
      </geometry>
      <material
        name="">
        <color
          rgba="0.792156862745098 0.819607843137255 0.933333333333333 1" />
      </material>
    </visual>
    <collision>
      <origin
        xyz="0 0 0"
        rpy="0 0 0" />
      <geometry>
        <mesh
          filename="package://diffdrivebot/meshes/base_link.STL" />
      </geometry>
    </collision>
  </link>
  <link
    name="left_link">
    <inertial>
      <origin
        xyz="0 -0.0190218340611354 0"
        rpy="0 0 0" />
      <mass
        value="0.215827415301619" />
      <inertia
        ixx="0.000123433445533082"
        ixy="7.83452221612012E-22"
        ixz="2.73872631878343E-21"
        iyy="0.00019474241985751"
        iyz="-2.20269327702413E-21"
        izz="0.000123433445533082" />
    </inertial>
    <visual>
      <origin
        xyz="0 0 0"
        rpy="0 0 0" />
      <geometry>
        <mesh
          filename="package://diffdrivebot/meshes/left_link.STL" />
      </geometry>
      <material
        name="">
        <color
          rgba="0.792156862745098 0.819607843137255 0.933333333333333 1" />
      </material>
    </visual>
    <collision>
      <origin
        xyz="0 0 0"
        rpy="0 0 0" />
      <geometry>
        <mesh
          filename="package://diffdrivebot/meshes/left_link.STL" />
      </geometry>
    </collision>
  </link>
  <joint
    name="left_wheel"
    type="continuous">
    <origin
      xyz="-0.1378 0.141 -0.042"
      rpy="0 0 0" />
    <parent
      link="base_link" />
    <child
      link="left_link" />
    <axis
      xyz="0 -1 0" />
    <limit
      effort="1"
      velocity="10" />
  </joint>
  <link
    name="right_link">
    <inertial>
      <origin
        xyz="2.77555756156289E-17 0.0190218340611354 6.93889390390723E-18"
        rpy="0 0 0" />
      <mass
        value="0.215827415301619" />
      <inertia
        ixx="0.000123433445533082"
        ixy="1.05036450747826E-19"
        ixz="8.11218086604348E-22"
        iyy="0.00019474241985751"
        iyz="1.30921085554886E-23"
        izz="0.000123433445533082" />
    </inertial>
    <visual>
      <origin
        xyz="0 0 0"
        rpy="0 0 0" />
      <geometry>
        <mesh
          filename="package://diffdrivebot/meshes/right_link.STL" />
      </geometry>
      <material
        name="">
        <color
          rgba="0.792156862745098 0.819607843137255 0.933333333333333 1" />
      </material>
    </visual>
    <collision>
      <origin
        xyz="0 0 0"
        rpy="0 0 0" />
      <geometry>
        <mesh
          filename="package://diffdrivebot/meshes/right_link.STL" />
      </geometry>
    </collision>
  </link>
  <joint
    name="right_wheel"
    type="continuous">
    <origin
      xyz="-0.1378 -0.141 -0.042"
      rpy="0 0 0" />
    <parent
      link="base_link" />
    <child
      link="right_link" />
    <axis
      xyz="0 -1 0" />
    <limit
      effort="1"
      velocity="10" />
  </joint>
</robot>